2018-09-06 23:37:20 ERROR (SyncWorker_8) [homeassistant.components.sensor.rest] Error fetching data: <PreparedRequest [POST]> from https://nodes.devnet.thetangle.org:443/ failed with HTTPSConnectionPool(host='nodes.devnet.thetangle.org', port=443): Max retries exceeded with url: / (Caused by NewConnectionError('<urllib3.connection.VerifiedHTTPSConnection object at 0x11470c2e8>: Failed to establish a new connection: [Errno 8] nodename nor servname provided, or not known',))
2018-09-06 23:37:20 ERROR (SyncWorker_7) [homeassistant.components.sensor.rest] Error fetching data: <PreparedRequest [POST]> from https://nodes.devnet.thetangle.org:443/ failed with HTTPSConnectionPool(host='nodes.devnet.thetangle.org', port=443): Max retries exceeded with url: / (Caused by NewConnectionError('<urllib3.connection.VerifiedHTTPSConnection object at 0x11470c358>: Failed to establish a new connection: [Errno 8] nodename nor servname provided, or not known',))
2018-09-06 23:37:20 ERROR (SyncWorker_2) [homeassistant.components.sensor.rest] Error fetching data: <PreparedRequest [POST]> from https://nodes.devnet.thetangle.org:443/ failed with HTTPSConnectionPool(host='nodes.devnet.thetangle.org', port=443): Max retries exceeded with url: / (Caused by NewConnectionError('<urllib3.connection.VerifiedHTTPSConnection object at 0x114726320>: Failed to establish a new connection: [Errno 8] nodename nor servname provided, or not known',))
2018-09-06 23:37:20 ERROR (SyncWorker_9) [homeassistant.components.sensor.rest] Error fetching data: <PreparedRequest [POST]> from https://nodes.devnet.thetangle.org:443/ failed with HTTPSConnectionPool(host='nodes.devnet.thetangle.org', port=443): Max retries exceeded with url: / (Caused by NewConnectionError('<urllib3.connection.VerifiedHTTPSConnection object at 0x1147265f8>: Failed to establish a new connection: [Errno 8] nodename nor servname provided, or not known',))
2018-09-06 23:37:20 ERROR (SyncWorker_10) [homeassistant.components.sensor.rest] Error fetching data: <PreparedRequest [POST]> from https://nodes.devnet.thetangle.org:443/ failed with HTTPSConnectionPool(host='nodes.devnet.thetangle.org', port=443): Max retries exceeded with url: / (Caused by NewConnectionError('<urllib3.connection.VerifiedHTTPSConnection object at 0x11480aac8>: Failed to establish a new connection: [Errno 8] nodename nor servname provided, or not known',))
2018-09-06 23:37:20 ERROR (SyncWorker_12) [homeassistant.components.sensor.rest] Error fetching data: <PreparedRequest [POST]> from https://nodes.devnet.thetangle.org:443/ failed with HTTPSConnectionPool(host='nodes.devnet.thetangle.org', port=443): Max retries exceeded with url: / (Caused by NewConnectionError('<urllib3.connection.VerifiedHTTPSConnection object at 0x114824710>: Failed to establish a new connection: [Errno 8] nodename nor servname provided, or not known',))
2018-09-06 23:37:21 ERROR (SyncWorker_14) [homeassistant.components.sensor.rest] Error fetching data: <PreparedRequest [POST]> from https://nodes.devnet.thetangle.org:443/ failed with HTTPSConnectionPool(host='nodes.devnet.thetangle.org', port=443): Max retries exceeded with url: / (Caused by NewConnectionError('<urllib3.connection.VerifiedHTTPSConnection object at 0x114824978>: Failed to establish a new connection: [Errno 8] nodename nor servname provided, or not known',))
2018-09-06 23:37:21 ERROR (SyncWorker_4) [homeassistant.components.sensor.rest] Error fetching data: <PreparedRequest [POST]> from https://nodes.devnet.thetangle.org:443/ failed with HTTPSConnectionPool(host='nodes.devnet.thetangle.org', port=443): Max retries exceeded with url: / (Caused by NewConnectionError('<urllib3.connection.VerifiedHTTPSConnection object at 0x114824ac8>: Failed to establish a new connection: [Errno 8] nodename nor servname provided, or not known',))
2018-09-06 23:37:21 ERROR (MainThread) [homeassistant.components.notify] Error setting up platform slack
Traceback (most recent call last):
  File "/Library/Frameworks/Python.framework/Versions/3.6/lib/python3.6/site-packages/urllib3/connection.py", line 141, in _new_conn
    (self.host, self.port), self.timeout, **extra_kw)
  File "/Library/Frameworks/Python.framework/Versions/3.6/lib/python3.6/site-packages/urllib3/util/connection.py", line 60, in create_connection
    for res in socket.getaddrinfo(host, port, family, socket.SOCK_STREAM):
  File "/Library/Frameworks/Python.framework/Versions/3.6/lib/python3.6/socket.py", line 745, in getaddrinfo
    for res in _socket.getaddrinfo(host, port, family, type, proto, flags):
socket.gaierror: [Errno 8] nodename nor servname provided, or not known

During handling of the above exception, another exception occurred:

Traceback (most recent call last):
  File "/Library/Frameworks/Python.framework/Versions/3.6/lib/python3.6/site-packages/urllib3/connectionpool.py", line 601, in urlopen
    chunked=chunked)
  File "/Library/Frameworks/Python.framework/Versions/3.6/lib/python3.6/site-packages/urllib3/connectionpool.py", line 346, in _make_request
    self._validate_conn(conn)
  File "/Library/Frameworks/Python.framework/Versions/3.6/lib/python3.6/site-packages/urllib3/connectionpool.py", line 850, in _validate_conn
    conn.connect()
  File "/Library/Frameworks/Python.framework/Versions/3.6/lib/python3.6/site-packages/urllib3/connection.py", line 284, in connect
    conn = self._new_conn()
  File "/Library/Frameworks/Python.framework/Versions/3.6/lib/python3.6/site-packages/urllib3/connection.py", line 150, in _new_conn
    self, "Failed to establish a new connection: %s" % e)
urllib3.exceptions.NewConnectionError: <urllib3.connection.VerifiedHTTPSConnection object at 0x11485ef28>: Failed to establish a new connection: [Errno 8] nodename nor servname provided, or not known

During handling of the above exception, another exception occurred:

Traceback (most recent call last):
  File "/Library/Frameworks/Python.framework/Versions/3.6/lib/python3.6/site-packages/requests/adapters.py", line 445, in send
    timeout=timeout
  File "/Library/Frameworks/Python.framework/Versions/3.6/lib/python3.6/site-packages/urllib3/connectionpool.py", line 639, in urlopen
    _stacktrace=sys.exc_info()[2])
  File "/Library/Frameworks/Python.framework/Versions/3.6/lib/python3.6/site-packages/urllib3/util/retry.py", line 388, in increment
    raise MaxRetryError(_pool, url, error or ResponseError(cause))
urllib3.exceptions.MaxRetryError: HTTPSConnectionPool(host='slack.com', port=443): Max retries exceeded with url: /api/auth.test?token=xoxb-412777719570-412779266290-0Mql8RkWNzSbIYG8hg1GBhHw (Caused by NewConnectionError('<urllib3.connection.VerifiedHTTPSConnection object at 0x11485ef28>: Failed to establish a new connection: [Errno 8] nodename nor servname provided, or not known',))

During handling of the above exception, another exception occurred:

Traceback (most recent call last):
  File "/Library/Frameworks/Python.framework/Versions/3.6/lib/python3.6/site-packages/homeassistant/components/notify/__init__.py", line 95, in async_setup_platform
    platform.get_service, hass, p_config, discovery_info)
  File "/Library/Frameworks/Python.framework/Versions/3.6/lib/python3.6/concurrent/futures/thread.py", line 56, in run
    result = self.fn(*self.args, **self.kwargs)
  File "/Library/Frameworks/Python.framework/Versions/3.6/lib/python3.6/site-packages/homeassistant/components/notify/slack.py", line 57, in get_service
    channel, api_key, username, icon, hass.config.is_allowed_path)
  File "/Library/Frameworks/Python.framework/Versions/3.6/lib/python3.6/site-packages/homeassistant/components/notify/slack.py", line 82, in __init__
    self.slack.auth.test()
  File "/Users/mac/.homeassistant/deps/lib/python/site-packages/slacker/__init__.py", line 137, in test
    return self.get('auth.test')
  File "/Users/mac/.homeassistant/deps/lib/python/site-packages/slacker/__init__.py", line 117, in get
    api, **kwargs
  File "/Users/mac/.homeassistant/deps/lib/python/site-packages/slacker/__init__.py", line 94, in _request
    **kwargs)
  File "/Library/Frameworks/Python.framework/Versions/3.6/lib/python3.6/site-packages/requests/api.py", line 72, in get
    return request('get', url, params=params, **kwargs)
  File "/Library/Frameworks/Python.framework/Versions/3.6/lib/python3.6/site-packages/requests/api.py", line 58, in request
    return session.request(method=method, url=url, **kwargs)
  File "/Library/Frameworks/Python.framework/Versions/3.6/lib/python3.6/site-packages/requests/sessions.py", line 512, in request
    resp = self.send(prep, **send_kwargs)
  File "/Library/Frameworks/Python.framework/Versions/3.6/lib/python3.6/site-packages/requests/sessions.py", line 622, in send
    r = adapter.send(request, **kwargs)
  File "/Library/Frameworks/Python.framework/Versions/3.6/lib/python3.6/site-packages/requests/adapters.py", line 513, in send
    raise ConnectionError(e, request=request)
requests.exceptions.ConnectionError: HTTPSConnectionPool(host='slack.com', port=443): Max retries exceeded with url: /api/auth.test?token=xoxb-412777719570-412779266290-0Mql8RkWNzSbIYG8hg1GBhHw (Caused by NewConnectionError('<urllib3.connection.VerifiedHTTPSConnection object at 0x11485ef28>: Failed to establish a new connection: [Errno 8] nodename nor servname provided, or not known',))
2018-09-06 23:37:21 ERROR (MainThread) [homeassistant.components.sensor.yr] Retrying in 15 minutes: Cannot connect to host aa015h6buqvih86i1.api.met.no:443 ssl:None [nodename nor servname provided, or not known]
2018-09-06 23:37:22 ERROR (MainThread) [homeassistant.components.cloud] Error fetching Cognito keyset: Cannot connect to host cognito-idp.us-east-1.amazonaws.com:443 ssl:None [nodename nor servname provided, or not known]
2018-09-06 23:37:22 ERROR (MainThread) [homeassistant.core] Error doing job: Task exception was never retrieved
Traceback (most recent call last):
  File "/Library/Frameworks/Python.framework/Versions/3.6/lib/python3.6/site-packages/homeassistant/components/discovery.py", line 167, in scan_devices
    results = await hass.async_add_job(_discover, netdisco)
  File "/Library/Frameworks/Python.framework/Versions/3.6/lib/python3.6/concurrent/futures/thread.py", line 56, in run
    result = self.fn(*self.args, **self.kwargs)
  File "/Library/Frameworks/Python.framework/Versions/3.6/lib/python3.6/site-packages/homeassistant/components/discovery.py", line 193, in _discover
    netdisco.scan()
  File "/Users/mac/.homeassistant/deps/lib/python/site-packages/netdisco/discovery.py", line 60, in scan
    self.gdm.scan()
  File "/Users/mac/.homeassistant/deps/lib/python/site-packages/netdisco/gdm.py", line 22, in scan
    self.update()
  File "/Users/mac/.homeassistant/deps/lib/python/site-packages/netdisco/gdm.py", line 77, in update
    sock.sendto(gdm_msg, (gdm_ip, gdm_port))
OSError: [Errno 51] Network is unreachable
2018-09-06 23:37:28 ERROR (MainThread) [homeassistant.components.cloud] Error fetching Cognito keyset: Cannot connect to host cognito-idp.us-east-1.amazonaws.com:443 ssl:None [nodename nor servname provided, or not known]
2018-09-06 23:37:34 ERROR (MainThread) [homeassistant.components.cloud] Error fetching Cognito keyset: Cannot connect to host cognito-idp.us-east-1.amazonaws.com:443 ssl:None [nodename nor servname provided, or not known]
2018-09-06 23:37:40 ERROR (MainThread) [homeassistant.components.cloud] Error fetching Cognito keyset: Cannot connect to host cognito-idp.us-east-1.amazonaws.com:443 ssl:None [nodename nor servname provided, or not known]
2018-09-06 23:37:46 ERROR (MainThread) [homeassistant.components.cloud] Error fetching Cognito keyset: Cannot connect to host cognito-idp.us-east-1.amazonaws.com:443 ssl:None [nodename nor servname provided, or not known]
2018-09-06 23:37:51 ERROR (SyncWorker_12) [homeassistant.components.sensor.rest] Error fetching data: <PreparedRequest [POST]> from https://nodes.devnet.thetangle.org:443/ failed with HTTPSConnectionPool(host='nodes.devnet.thetangle.org', port=443): Max retries exceeded with url: / (Caused by NewConnectionError('<urllib3.connection.VerifiedHTTPSConnection object at 0x11589e4e0>: Failed to establish a new connection: [Errno 8] nodename nor servname provided, or not known',))
2018-09-06 23:37:51 ERROR (SyncWorker_13) [homeassistant.components.sensor.rest] Error fetching data: <PreparedRequest [POST]> from https://nodes.devnet.thetangle.org:443/ failed with HTTPSConnectionPool(host='nodes.devnet.thetangle.org', port=443): Max retries exceeded with url: / (Caused by NewConnectionError('<urllib3.connection.VerifiedHTTPSConnection object at 0x11589ee80>: Failed to establish a new connection: [Errno 8] nodename nor servname provided, or not known',))
2018-09-06 23:37:51 ERROR (SyncWorker_0) [homeassistant.components.sensor.rest] Error fetching data: <PreparedRequest [POST]> from https://nodes.devnet.thetangle.org:443/ failed with HTTPSConnectionPool(host='nodes.devnet.thetangle.org', port=443): Max retries exceeded with url: / (Caused by NewConnectionError('<urllib3.connection.VerifiedHTTPSConnection object at 0x11589e4e0>: Failed to establish a new connection: [Errno 8] nodename nor servname provided, or not known',))
2018-09-06 23:37:51 ERROR (SyncWorker_15) [homeassistant.components.sensor.rest] Error fetching data: <PreparedRequest [POST]> from https://nodes.devnet.thetangle.org:443/ failed with HTTPSConnectionPool(host='nodes.devnet.thetangle.org', port=443): Max retries exceeded with url: / (Caused by NewConnectionError('<urllib3.connection.VerifiedHTTPSConnection object at 0x11589ee80>: Failed to establish a new connection: [Errno 8] nodename nor servname provided, or not known',))
2018-09-06 23:37:52 ERROR (MainThread) [homeassistant.components.cloud] Error fetching Cognito keyset: Cannot connect to host cognito-idp.us-east-1.amazonaws.com:443 ssl:None [nodename nor servname provided, or not known]
2018-09-06 23:37:58 ERROR (MainThread) [homeassistant.components.cloud] Error fetching Cognito keyset: Cannot connect to host cognito-idp.us-east-1.amazonaws.com:443 ssl:None [nodename nor servname provided, or not known]
2018-09-06 23:38:04 ERROR (MainThread) [homeassistant.components.cloud] Error fetching Cognito keyset: Cannot connect to host cognito-idp.us-east-1.amazonaws.com:443 ssl:None [nodename nor servname provided, or not known]
2018-09-06 23:38:10 ERROR (MainThread) [homeassistant.components.cloud] Error fetching Cognito keyset: Cannot connect to host cognito-idp.us-east-1.amazonaws.com:443 ssl:None [nodename nor servname provided, or not known]
2018-09-06 23:38:16 ERROR (MainThread) [homeassistant.components.cloud] Error fetching Cognito keyset: Cannot connect to host cognito-idp.us-east-1.amazonaws.com:443 ssl:None [nodename nor servname provided, or not known]
2018-09-06 23:38:21 ERROR (SyncWorker_9) [homeassistant.components.sensor.rest] Error fetching data: <PreparedRequest [POST]> from https://nodes.devnet.thetangle.org:443/ failed with HTTPSConnectionPool(host='nodes.devnet.thetangle.org', port=443): Max retries exceeded with url: / (Caused by NewConnectionError('<urllib3.connection.VerifiedHTTPSConnection object at 0x11589e208>: Failed to establish a new connection: [Errno 8] nodename nor servname provided, or not known',))
2018-09-06 23:38:21 ERROR (SyncWorker_3) [homeassistant.components.sensor.rest] Error fetching data: <PreparedRequest [POST]> from https://nodes.devnet.thetangle.org:443/ failed with HTTPSConnectionPool(host='nodes.devnet.thetangle.org', port=443): Max retries exceeded with url: / (Caused by NewConnectionError('<urllib3.connection.VerifiedHTTPSConnection object at 0x11589e128>: Failed to establish a new connection: [Errno 8] nodename nor servname provided, or not known',))
2018-09-06 23:38:21 ERROR (SyncWorker_8) [homeassistant.components.sensor.rest] Error fetching data: <PreparedRequest [POST]> from https://nodes.devnet.thetangle.org:443/ failed with HTTPSConnectionPool(host='nodes.devnet.thetangle.org', port=443): Max retries exceeded with url: / (Caused by NewConnectionError('<urllib3.connection.VerifiedHTTPSConnection object at 0x11589e208>: Failed to establish a new connection: [Errno 8] nodename nor servname provided, or not known',))
2018-09-06 23:38:21 ERROR (SyncWorker_2) [homeassistant.components.sensor.rest] Error fetching data: <PreparedRequest [POST]> from https://nodes.devnet.thetangle.org:443/ failed with HTTPSConnectionPool(host='nodes.devnet.thetangle.org', port=443): Max retries exceeded with url: / (Caused by NewConnectionError('<urllib3.connection.VerifiedHTTPSConnection object at 0x11589e128>: Failed to establish a new connection: [Errno 8] nodename nor servname provided, or not known',))
2018-09-06 23:38:22 ERROR (MainThread) [homeassistant.components.cloud] Error fetching Cognito keyset: Cannot connect to host cognito-idp.us-east-1.amazonaws.com:443 ssl:None [nodename nor servname provided, or not known]
2018-09-06 23:38:28 ERROR (MainThread) [homeassistant.components.cloud] Error fetching Cognito keyset: Cannot connect to host cognito-idp.us-east-1.amazonaws.com:443 ssl:None [nodename nor servname provided, or not known]
2018-09-06 23:38:34 ERROR (MainThread) [homeassistant.components.cloud] Error fetching Cognito keyset: Cannot connect to host cognito-idp.us-east-1.amazonaws.com:443 ssl:None [nodename nor servname provided, or not known]
2018-09-06 23:38:40 ERROR (MainThread) [homeassistant.components.cloud] Error fetching Cognito keyset: Cannot connect to host cognito-idp.us-east-1.amazonaws.com:443 ssl:None [nodename nor servname provided, or not known]
2018-09-06 23:38:46 ERROR (MainThread) [homeassistant.components.cloud] Error fetching Cognito keyset: Cannot connect to host cognito-idp.us-east-1.amazonaws.com:443 ssl:None [nodename nor servname provided, or not known]
2018-09-06 23:38:51 ERROR (SyncWorker_0) [homeassistant.components.sensor.rest] Error fetching data: <PreparedRequest [POST]> from https://nodes.devnet.thetangle.org:443/ failed with HTTPSConnectionPool(host='nodes.devnet.thetangle.org', port=443): Max retries exceeded with url: / (Caused by NewConnectionError('<urllib3.connection.VerifiedHTTPSConnection object at 0x11589e358>: Failed to establish a new connection: [Errno 8] nodename nor servname provided, or not known',))
2018-09-06 23:38:51 ERROR (SyncWorker_15) [homeassistant.components.sensor.rest] Error fetching data: <PreparedRequest [POST]> from https://nodes.devnet.thetangle.org:443/ failed with HTTPSConnectionPool(host='nodes.devnet.thetangle.org', port=443): Max retries exceeded with url: / (Caused by NewConnectionError('<urllib3.connection.VerifiedHTTPSConnection object at 0x11589eef0>: Failed to establish a new connection: [Errno 8] nodename nor servname provided, or not known',))
2018-09-06 23:38:51 ERROR (SyncWorker_14) [homeassistant.components.sensor.rest] Error fetching data: <PreparedRequest [POST]> from https://nodes.devnet.thetangle.org:443/ failed with HTTPSConnectionPool(host='nodes.devnet.thetangle.org', port=443): Max retries exceeded with url: / (Caused by NewConnectionError('<urllib3.connection.VerifiedHTTPSConnection object at 0x11589e358>: Failed to establish a new connection: [Errno 8] nodename nor servname provided, or not known',))
2018-09-06 23:38:51 ERROR (SyncWorker_17) [homeassistant.components.sensor.rest] Error fetching data: <PreparedRequest [POST]> from https://nodes.devnet.thetangle.org:443/ failed with HTTPSConnectionPool(host='nodes.devnet.thetangle.org', port=443): Max retries exceeded with url: / (Caused by NewConnectionError('<urllib3.connection.VerifiedHTTPSConnection object at 0x11589eef0>: Failed to establish a new connection: [Errno 8] nodename nor servname provided, or not known',))
2018-09-06 23:38:52 ERROR (MainThread) [homeassistant.components.cloud] Error fetching Cognito keyset: Cannot connect to host cognito-idp.us-east-1.amazonaws.com:443 ssl:None [nodename nor servname provided, or not known]
2018-09-06 23:38:58 ERROR (MainThread) [homeassistant.components.cloud] Error fetching Cognito keyset: Cannot connect to host cognito-idp.us-east-1.amazonaws.com:443 ssl:None [nodename nor servname provided, or not known]
2018-09-06 23:39:04 ERROR (MainThread) [homeassistant.components.cloud] Error fetching Cognito keyset: Cannot connect to host cognito-idp.us-east-1.amazonaws.com:443 ssl:None [nodename nor servname provided, or not known]
2018-09-06 23:39:09 ERROR (MainThread) [homeassistant.components.cloud] Error fetching Cognito keyset: Cannot connect to host cognito-idp.us-east-1.amazonaws.com:443 ssl:None [nodename nor servname provided, or not known]
2018-09-06 23:39:15 ERROR (MainThread) [homeassistant.components.cloud] Error fetching Cognito keyset: Cannot connect to host cognito-idp.us-east-1.amazonaws.com:443 ssl:None [nodename nor servname provided, or not known]
2018-09-06 23:39:21 ERROR (MainThread) [homeassistant.components.cloud] Error fetching Cognito keyset: Cannot connect to host cognito-idp.us-east-1.amazonaws.com:443 ssl:None [nodename nor servname provided, or not known]
2018-09-06 23:39:21 ERROR (SyncWorker_2) [homeassistant.components.sensor.rest] Error fetching data: <PreparedRequest [POST]> from https://nodes.devnet.thetangle.org:443/ failed with HTTPSConnectionPool(host='nodes.devnet.thetangle.org', port=443): Max retries exceeded with url: / (Caused by NewConnectionError('<urllib3.connection.VerifiedHTTPSConnection object at 0x115899160>: Failed to establish a new connection: [Errno 8] nodename nor servname provided, or not known',))
2018-09-06 23:39:21 ERROR (SyncWorker_11) [homeassistant.components.sensor.rest] Error fetching data: <PreparedRequest [POST]> from https://nodes.devnet.thetangle.org:443/ failed with HTTPSConnectionPool(host='nodes.devnet.thetangle.org', port=443): Max retries exceeded with url: / (Caused by NewConnectionError('<urllib3.connection.VerifiedHTTPSConnection object at 0x115899be0>: Failed to establish a new connection: [Errno 8] nodename nor servname provided, or not known',))
2018-09-06 23:39:21 ERROR (SyncWorker_6) [homeassistant.components.sensor.rest] Error fetching data: <PreparedRequest [POST]> from https://nodes.devnet.thetangle.org:443/ failed with HTTPSConnectionPool(host='nodes.devnet.thetangle.org', port=443): Max retries exceeded with url: / (Caused by NewConnectionError('<urllib3.connection.VerifiedHTTPSConnection object at 0x115899c88>: Failed to establish a new connection: [Errno 8] nodename nor servname provided, or not known',))
2018-09-06 23:39:21 ERROR (SyncWorker_5) [homeassistant.components.sensor.rest] Error fetching data: <PreparedRequest [POST]> from https://nodes.devnet.thetangle.org:443/ failed with HTTPSConnectionPool(host='nodes.devnet.thetangle.org', port=443): Max retries exceeded with url: / (Caused by NewConnectionError('<urllib3.connection.VerifiedHTTPSConnection object at 0x115899128>: Failed to establish a new connection: [Errno 8] nodename nor servname provided, or not known',))
2018-09-06 23:39:27 ERROR (MainThread) [homeassistant.components.cloud] Error fetching Cognito keyset: Cannot connect to host cognito-idp.us-east-1.amazonaws.com:443 ssl:None [nodename nor servname provided, or not known]
2018-09-06 23:39:33 ERROR (MainThread) [homeassistant.components.cloud] Error fetching Cognito keyset: Cannot connect to host cognito-idp.us-east-1.amazonaws.com:443 ssl:None [nodename nor servname provided, or not known]
2018-09-06 23:39:39 ERROR (MainThread) [homeassistant.components.cloud] Error fetching Cognito keyset: Cannot connect to host cognito-idp.us-east-1.amazonaws.com:443 ssl:None [nodename nor servname provided, or not known]
2018-09-06 23:39:45 ERROR (MainThread) [homeassistant.components.cloud] Error fetching Cognito keyset: Cannot connect to host cognito-idp.us-east-1.amazonaws.com:443 ssl:None [nodename nor servname provided, or not known]
2018-09-06 23:39:51 ERROR (SyncWorker_17) [homeassistant.components.sensor.rest] Error fetching data: <PreparedRequest [POST]> from https://nodes.devnet.thetangle.org:443/ failed with HTTPSConnectionPool(host='nodes.devnet.thetangle.org', port=443): Max retries exceeded with url: / (Caused by NewConnectionError('<urllib3.connection.VerifiedHTTPSConnection object at 0x115899080>: Failed to establish a new connection: [Errno 8] nodename nor servname provided, or not known',))
2018-09-06 23:39:51 ERROR (MainThread) [homeassistant.components.cloud] Error fetching Cognito keyset: Cannot connect to host cognito-idp.us-east-1.amazonaws.com:443 ssl:None [nodename nor servname provided, or not known]
2018-09-06 23:39:51 ERROR (SyncWorker_16) [homeassistant.components.sensor.rest] Error fetching data: <PreparedRequest [POST]> from https://nodes.devnet.thetangle.org:443/ failed with HTTPSConnectionPool(host='nodes.devnet.thetangle.org', port=443): Max retries exceeded with url: / (Caused by NewConnectionError('<urllib3.connection.VerifiedHTTPSConnection object at 0x1158999e8>: Failed to establish a new connection: [Errno 8] nodename nor servname provided, or not known',))
2018-09-06 23:39:51 ERROR (SyncWorker_4) [homeassistant.components.sensor.rest] Error fetching data: <PreparedRequest [POST]> from https://nodes.devnet.thetangle.org:443/ failed with HTTPSConnectionPool(host='nodes.devnet.thetangle.org', port=443): Max retries exceeded with url: / (Caused by NewConnectionError('<urllib3.connection.VerifiedHTTPSConnection object at 0x115899908>: Failed to establish a new connection: [Errno 8] nodename nor servname provided, or not known',))
2018-09-06 23:39:51 ERROR (SyncWorker_18) [homeassistant.components.sensor.rest] Error fetching data: <PreparedRequest [POST]> from https://nodes.devnet.thetangle.org:443/ failed with HTTPSConnectionPool(host='nodes.devnet.thetangle.org', port=443): Max retries exceeded with url: / (Caused by NewConnectionError('<urllib3.connection.VerifiedHTTPSConnection object at 0x1158999e8>: Failed to establish a new connection: [Errno 8] nodename nor servname provided, or not known',))
2018-09-06 23:39:57 ERROR (MainThread) [homeassistant.components.cloud] Error fetching Cognito keyset: Cannot connect to host cognito-idp.us-east-1.amazonaws.com:443 ssl:None [nodename nor servname provided, or not known]
2018-09-06 23:40:03 ERROR (MainThread) [homeassistant.components.cloud] Error fetching Cognito keyset: Cannot connect to host cognito-idp.us-east-1.amazonaws.com:443 ssl:None [nodename nor servname provided, or not known]
2018-09-06 23:40:09 ERROR (MainThread) [homeassistant.components.cloud] Error fetching Cognito keyset: Cannot connect to host cognito-idp.us-east-1.amazonaws.com:443 ssl:None [nodename nor servname provided, or not known]
2018-09-06 23:40:15 ERROR (MainThread) [homeassistant.components.cloud] Error fetching Cognito keyset: Cannot connect to host cognito-idp.us-east-1.amazonaws.com:443 ssl:None [nodename nor servname provided, or not known]
2018-09-06 23:40:21 ERROR (SyncWorker_6) [homeassistant.components.sensor.rest] Error fetching data: <PreparedRequest [POST]> from https://nodes.devnet.thetangle.org:443/ failed with HTTPSConnectionPool(host='nodes.devnet.thetangle.org', port=443): Max retries exceeded with url: / (Caused by NewConnectionError('<urllib3.connection.VerifiedHTTPSConnection object at 0x115899198>: Failed to establish a new connection: [Errno 8] nodename nor servname provided, or not known',))
2018-09-06 23:40:21 ERROR (MainThread) [homeassistant.components.cloud] Error fetching Cognito keyset: Cannot connect to host cognito-idp.us-east-1.amazonaws.com:443 ssl:None [nodename nor servname provided, or not known]
2018-09-06 23:40:21 ERROR (SyncWorker_5) [homeassistant.components.sensor.rest] Error fetching data: <PreparedRequest [POST]> from https://nodes.devnet.thetangle.org:443/ failed with HTTPSConnectionPool(host='nodes.devnet.thetangle.org', port=443): Max retries exceeded with url: / (Caused by NewConnectionError('<urllib3.connection.VerifiedHTTPSConnection object at 0x115899eb8>: Failed to establish a new connection: [Errno 8] nodename nor servname provided, or not known',))
2018-09-06 23:40:21 ERROR (SyncWorker_10) [homeassistant.components.sensor.rest] Error fetching data: <PreparedRequest [POST]> from https://nodes.devnet.thetangle.org:443/ failed with HTTPSConnectionPool(host='nodes.devnet.thetangle.org', port=443): Max retries exceeded with url: / (Caused by NewConnectionError('<urllib3.connection.VerifiedHTTPSConnection object at 0x1158992e8>: Failed to establish a new connection: [Errno 8] nodename nor servname provided, or not known',))
2018-09-06 23:40:21 ERROR (SyncWorker_1) [homeassistant.components.sensor.rest] Error fetching data: <PreparedRequest [POST]> from https://nodes.devnet.thetangle.org:443/ failed with HTTPSConnectionPool(host='nodes.devnet.thetangle.org', port=443): Max retries exceeded with url: / (Caused by NewConnectionError('<urllib3.connection.VerifiedHTTPSConnection object at 0x115899eb8>: Failed to establish a new connection: [Errno 8] nodename nor servname provided, or not known',))
2018-09-06 23:40:27 ERROR (MainThread) [homeassistant.components.cloud] Error fetching Cognito keyset: Cannot connect to host cognito-idp.us-east-1.amazonaws.com:443 ssl:None [nodename nor servname provided, or not known]
2018-09-06 23:40:33 ERROR (MainThread) [homeassistant.components.cloud] Error fetching Cognito keyset: Cannot connect to host cognito-idp.us-east-1.amazonaws.com:443 ssl:None [nodename nor servname provided, or not known]
2018-09-06 23:40:39 ERROR (MainThread) [homeassistant.components.cloud] Error fetching Cognito keyset: Cannot connect to host cognito-idp.us-east-1.amazonaws.com:443 ssl:None [nodename nor servname provided, or not known]
2018-09-06 23:40:45 ERROR (MainThread) [homeassistant.components.cloud] Error fetching Cognito keyset: Cannot connect to host cognito-idp.us-east-1.amazonaws.com:443 ssl:None [nodename nor servname provided, or not known]
2018-09-06 23:40:51 ERROR (SyncWorker_4) [homeassistant.components.sensor.rest] Error fetching data: <PreparedRequest [POST]> from https://nodes.devnet.thetangle.org:443/ failed with HTTPSConnectionPool(host='nodes.devnet.thetangle.org', port=443): Max retries exceeded with url: / (Caused by NewConnectionError('<urllib3.connection.VerifiedHTTPSConnection object at 0x115899c50>: Failed to establish a new connection: [Errno 8] nodename nor servname provided, or not known',))
2018-09-06 23:40:51 ERROR (MainThread) [homeassistant.components.cloud] Error fetching Cognito keyset: Cannot connect to host cognito-idp.us-east-1.amazonaws.com:443 ssl:None [nodename nor servname provided, or not known]
2018-09-06 23:40:51 ERROR (SyncWorker_18) [homeassistant.components.sensor.rest] Error fetching data: <PreparedRequest [POST]> from https://nodes.devnet.thetangle.org:443/ failed with HTTPSConnectionPool(host='nodes.devnet.thetangle.org', port=443): Max retries exceeded with url: / (Caused by NewConnectionError('<urllib3.connection.VerifiedHTTPSConnection object at 0x1158995c0>: Failed to establish a new connection: [Errno 8] nodename nor servname provided, or not known',))
2018-09-06 23:40:51 ERROR (SyncWorker_19) [homeassistant.components.sensor.rest] Error fetching data: <PreparedRequest [POST]> from https://nodes.devnet.thetangle.org:443/ failed with HTTPSConnectionPool(host='nodes.devnet.thetangle.org', port=443): Max retries exceeded with url: / (Caused by NewConnectionError('<urllib3.connection.VerifiedHTTPSConnection object at 0x1158999e8>: Failed to establish a new connection: [Errno 8] nodename nor servname provided, or not known',))
2018-09-06 23:40:51 ERROR (SyncWorker_7) [homeassistant.components.sensor.rest] Error fetching data: <PreparedRequest [POST]> from https://nodes.devnet.thetangle.org:443/ failed with HTTPSConnectionPool(host='nodes.devnet.thetangle.org', port=443): Max retries exceeded with url: / (Caused by NewConnectionError('<urllib3.connection.VerifiedHTTPSConnection object at 0x1158995c0>: Failed to establish a new connection: [Errno 8] nodename nor servname provided, or not known',))
2018-09-06 23:40:57 ERROR (MainThread) [homeassistant.components.cloud] Error fetching Cognito keyset: Cannot connect to host cognito-idp.us-east-1.amazonaws.com:443 ssl:None [nodename nor servname provided, or not known]
2018-09-06 23:41:03 ERROR (MainThread) [homeassistant.components.cloud] Error fetching Cognito keyset: Cannot connect to host cognito-idp.us-east-1.amazonaws.com:443 ssl:None [nodename nor servname provided, or not known]
2018-09-06 23:41:09 ERROR (MainThread) [homeassistant.components.cloud] Error fetching Cognito keyset: Cannot connect to host cognito-idp.us-east-1.amazonaws.com:443 ssl:None [nodename nor servname provided, or not known]
2018-09-06 23:41:14 ERROR (MainThread) [homeassistant.components.cloud] Error fetching Cognito keyset: Cannot connect to host cognito-idp.us-east-1.amazonaws.com:443 ssl:None [nodename nor servname provided, or not known]
2018-09-06 23:41:20 ERROR (MainThread) [homeassistant.components.cloud] Error fetching Cognito keyset: Cannot connect to host cognito-idp.us-east-1.amazonaws.com:443 ssl:None [nodename nor servname provided, or not known]
2018-09-06 23:41:22 ERROR (SyncWorker_10) [homeassistant.components.sensor.rest] Error fetching data: <PreparedRequest [POST]> from https://nodes.devnet.thetangle.org:443/ failed with HTTPSConnectionPool(host='nodes.devnet.thetangle.org', port=443): Max retries exceeded with url: / (Caused by NewConnectionError('<urllib3.connection.VerifiedHTTPSConnection object at 0x1158992e8>: Failed to establish a new connection: [Errno 8] nodename nor servname provided, or not known',))
2018-09-06 23:41:22 ERROR (SyncWorker_1) [homeassistant.components.sensor.rest] Error fetching data: <PreparedRequest [POST]> from https://nodes.devnet.thetangle.org:443/ failed with HTTPSConnectionPool(host='nodes.devnet.thetangle.org', port=443): Max retries exceeded with url: / (Caused by NewConnectionError('<urllib3.connection.VerifiedHTTPSConnection object at 0x115899320>: Failed to establish a new connection: [Errno 8] nodename nor servname provided, or not known',))
2018-09-06 23:41:22 ERROR (SyncWorker_12) [homeassistant.components.sensor.rest] Error fetching data: <PreparedRequest [POST]> from https://nodes.devnet.thetangle.org:443/ failed with HTTPSConnectionPool(host='nodes.devnet.thetangle.org', port=443): Max retries exceeded with url: / (Caused by NewConnectionError('<urllib3.connection.VerifiedHTTPSConnection object at 0x1158992e8>: Failed to establish a new connection: [Errno 8] nodename nor servname provided, or not known',))
2018-09-06 23:41:22 ERROR (SyncWorker_13) [homeassistant.components.sensor.rest] Error fetching data: <PreparedRequest [POST]> from https://nodes.devnet.thetangle.org:443/ failed with HTTPSConnectionPool(host='nodes.devnet.thetangle.org', port=443): Max retries exceeded with url: / (Caused by NewConnectionError('<urllib3.connection.VerifiedHTTPSConnection object at 0x115899320>: Failed to establish a new connection: [Errno 8] nodename nor servname provided, or not known',))
2018-09-06 23:41:26 ERROR (MainThread) [homeassistant.components.cloud] Error fetching Cognito keyset: Cannot connect to host cognito-idp.us-east-1.amazonaws.com:443 ssl:None [nodename nor servname provided, or not known]
2018-09-06 23:41:32 ERROR (MainThread) [homeassistant.components.cloud] Error fetching Cognito keyset: Cannot connect to host cognito-idp.us-east-1.amazonaws.com:443 ssl:None [nodename nor servname provided, or not known]
2018-09-06 23:43:37 WARNING (MainThread) [homeassistant.core] Unable to find service notify/slack_notification
2018-09-07 00:08:27 ERROR (MainThread) [homeassistant.core] Timer got out of sync. Resetting
2018-09-07 00:08:27 ERROR (SyncWorker_19) [homeassistant.components.sensor.rest] Error fetching data: <PreparedRequest [POST]> from https://nodes.devnet.thetangle.org:443/ failed with HTTPSConnectionPool(host='nodes.devnet.thetangle.org', port=443): Max retries exceeded with url: / (Caused by NewConnectionError('<urllib3.connection.VerifiedHTTPSConnection object at 0x115881080>: Failed to establish a new connection: [Errno 50] Network is down',))
2018-09-07 00:08:27 ERROR (SyncWorker_9) [homeassistant.components.sensor.rest] Error fetching data: <PreparedRequest [POST]> from https://nodes.devnet.thetangle.org:443/ failed with HTTPSConnectionPool(host='nodes.devnet.thetangle.org', port=443): Max retries exceeded with url: / (Caused by NewConnectionError('<urllib3.connection.VerifiedHTTPSConnection object at 0x1158a3320>: Failed to establish a new connection: [Errno 50] Network is down',))
2018-09-07 00:08:27 ERROR (SyncWorker_4) [homeassistant.components.sensor.rest] Error fetching data: <PreparedRequest [POST]> from https://nodes.devnet.thetangle.org:443/ failed with HTTPSConnectionPool(host='nodes.devnet.thetangle.org', port=443): Max retries exceeded with url: / (Caused by NewConnectionError('<urllib3.connection.VerifiedHTTPSConnection object at 0x1159059b0>: Failed to establish a new connection: [Errno 50] Network is down',))
2018-09-07 00:08:27 ERROR (SyncWorker_3) [homeassistant.components.sensor.rest] Error fetching data: <PreparedRequest [POST]> from https://nodes.devnet.thetangle.org:443/ failed with HTTPSConnectionPool(host='nodes.devnet.thetangle.org', port=443): Max retries exceeded with url: / (Caused by NewConnectionError('<urllib3.connection.VerifiedHTTPSConnection object at 0x115905e80>: Failed to establish a new connection: [Errno 50] Network is down',))
2018-09-07 00:46:31 ERROR (MainThread) [homeassistant.core] Timer got out of sync. Resetting
2018-09-07 01:23:36 ERROR (SyncWorker_13) [homeassistant.components.sensor.rest] Error fetching data: <PreparedRequest [POST]> from https://nodes.devnet.thetangle.org:443/ failed with HTTPSConnectionPool(host='nodes.devnet.thetangle.org', port=443): Max retries exceeded with url: / (Caused by NewConnectionError('<urllib3.connection.VerifiedHTTPSConnection object at 0x1158e8400>: Failed to establish a new connection: [Errno 50] Network is down',))
2018-09-07 01:23:36 ERROR (SyncWorker_2) [homeassistant.components.sensor.rest] Error fetching data: <PreparedRequest [POST]> from https://nodes.devnet.thetangle.org:443/ failed with HTTPSConnectionPool(host='nodes.devnet.thetangle.org', port=443): Max retries exceeded with url: / (Caused by NewConnectionError('<urllib3.connection.VerifiedHTTPSConnection object at 0x115913898>: Failed to establish a new connection: [Errno 50] Network is down',))
2018-09-07 01:23:36 ERROR (SyncWorker_5) [homeassistant.components.sensor.rest] Error fetching data: <PreparedRequest [POST]> from https://nodes.devnet.thetangle.org:443/ failed with HTTPSConnectionPool(host='nodes.devnet.thetangle.org', port=443): Max retries exceeded with url: / (Caused by NewConnectionError('<urllib3.connection.VerifiedHTTPSConnection object at 0x1158f80f0>: Failed to establish a new connection: [Errno 50] Network is down',))
2018-09-07 01:23:36 ERROR (SyncWorker_8) [homeassistant.components.sensor.rest] Error fetching data: <PreparedRequest [POST]> from https://nodes.devnet.thetangle.org:443/ failed with HTTPSConnectionPool(host='nodes.devnet.thetangle.org', port=443): Max retries exceeded with url: / (Caused by NewConnectionError('<urllib3.connection.VerifiedHTTPSConnection object at 0x1159b69b0>: Failed to establish a new connection: [Errno 50] Network is down',))
2018-09-07 01:25:43 WARNING (MainThread) [hbmqtt.mqtt.protocol.handler] BrokerProtocolHandler Unhandled exception in reader coro: IncompleteReadError('0 bytes read on a total of 1 expected bytes',)
2018-09-07 01:42:13 WARNING (MainThread) [homeassistant.core] Unable to find service notify/slack_notification
2018-09-07 01:47:41 WARNING (MainThread) [homeassistant.core] Unable to find service notify/slack_notification
2018-09-07 01:49:42 ERROR (MainThread) [homeassistant.components.websocket_api] WS 4636012048: Message incorrectly formatted: expected dict for dictionary value @ data['service_data']. Got 123 
2018-09-07 01:51:53 WARNING (MainThread) [homeassistant.core] Unable to find service notify/slack_notification
2018-09-07 01:53:23 WARNING (MainThread) [hbmqtt.mqtt.protocol.handler] BrokerProtocolHandler Unhandled exception in reader coro: IncompleteReadError('0 bytes read on a total of 1 expected bytes',)
